//----------------------------  trilinos_vector_assign_01.cc  ---------------------------
//    $Id$
//    Version: $Name$ 
//
//    Copyright (C) 2004, 2005 by the deal.II authors
//
//    This file is subject to QPL and may not be  distributed
//    without copyright and license information. Please refer
//    to the file deal.II/doc/license.html for the  text  and
//    further information on this license.
//
//----------------------------  trilinos_vector_assign_01.cc  ---------------------------


// when calling TrilinosWrappers::Vector::operator() (), the return type is a
// reference object, not a reference to the actual element. this leads to the
// funny situation that an assignment like v2(i)=v1(i) isn't really what it
// looks like: it tries to copy the reference objects, not the values they
// point to, as one would expect
//
// this was fixed 2004-04-05, and this test checks that it works

#include "../tests.h"
#include <lac/trilinos_vector.h>    
#include <fstream>
#include <iostream>
#include <vector>


void test (TrilinosWrappers::Vector &v,
           TrilinosWrappers::Vector &w)
{
                                   // set the first vector
  for (unsigned int i=0; i<v.size(); ++i)
    v(i) = i;

                                   // copy elements by reference
  for (unsigned int i=0; i<v.size(); ++i)
    w(i) = v(i);

                                   // check that they're equal
  Assert (v==w, ExcInternalError());

  deallog << "OK" << std::endl;
}



int main (int argc, char **argv)
{
  std::ofstream logfile("vector_assign_01/output");
  deallog.attach(logfile);
  deallog.depth_console(0);
  deallog.threshold_double(1.e-10);

  try
    {
      {
        TrilinosWrappers::Vector v (100);
        TrilinosWrappers::Vector w (100);
        test (v,w);
      }
    }
  catch (std::exception &exc)
    {
      std::cerr << std::endl << std::endl
		<< "----------------------------------------------------"
		<< std::endl;
      std::cerr << "Exception on processing: " << std::endl
		<< exc.what() << std::endl
		<< "Aborting!" << std::endl
		<< "----------------------------------------------------"
		<< std::endl;
      
      return 1;
    }
  catch (...) 
    {
      std::cerr << std::endl << std::endl
		<< "----------------------------------------------------"
		<< std::endl;
      std::cerr << "Unknown exception!" << std::endl
		<< "Aborting!" << std::endl
		<< "----------------------------------------------------"
		<< std::endl;
      return 1;
    };
}
